<?xml version="1.0" ?>
<robot name="masterHumanoid2025">
<!-- 색칠 태그 -->
  <material name="silver">
    <color rgba="0.700 0.700 0.700 1.000"/>
  </material>
  <material name="light_gray">
    <color rgba="0.85 0.85 0.85 1.0"/>
  </material>
  <material name="sky_blue">
    <color rgba="0.678 0.847 0.902 1.0"/>
  </material>
  <material name="mint_green">
    <color rgba="0.749 1.000 0.847 1.0"/>
  </material>
  <material name="peach">
    <color rgba="1.000 0.855 0.725 1.0"/>
  </material>
  <material name="lavender">
    <color rgba="0.902 0.902 0.980 1.0"/>
  </material>
  <material name="salmon">
    <color rgba="1.000 0.627 0.478 1.0"/>
  </material>
  <link name="base_link">
    <!-- mesh linking 수정 완 / mass value 수정 완 -->
    <inertial>
      <origin rpy="0 0 0" xyz="0.012834207217545641 -0.00028286488702963016 0.6512228716334499"/>
      <mass value="5.757"/>
      <inertia ixx="0.295311" ixy="0.000102" ixz="-0.010711" iyy="0.167039" iyz="-0.000117" izz="0.153413"/>
    </inertial>
    <visual>
      <origin rpy="0 0 0" xyz="0 0 0"/>
      <geometry>
        <mesh filename="file:///home/lwj/colcon_ws/install/masterHumanoid2025_description/share/masterHumanoid2025_description/meshes/base_link.stl" scale="0.001 0.001 0.001"/>
      </geometry>
      <material name="silver"/>
    </visual>
    <collision>
      <origin rpy="0 0 0" xyz="0 0 0"/>
      <geometry>
        <mesh filename="file:///home/lwj/colcon_ws/install/masterHumanoid2025_description/share/masterHumanoid2025_description/meshes/base_link.stl" scale="0.001 0.001 0.001"/>
      </geometry>
    </collision>
  </link>
  <link name="left_upper_frame_1">
    <inertial>
      <origin rpy="0 0 0" xyz="-0.00689471238167166 1.055781750963769e-05 -0.02090957090882195"/>
      <mass value="0.1555228615666778"/>
      <inertia ixx="0.000126" ixy="0.0" ixz="-2e-06" iyy="0.000495" iyz="-0.0" izz="0.000452"/>    </inertial>
    <visual>
      <origin rpy="0 0 0" xyz="-0.002061 -0.07965 -0.609638"/>
      <geometry>
        <mesh filename="file:///home/lwj/colcon_ws/install/masterHumanoid2025_description/share/masterHumanoid2025_description/meshes/left_upper_frame_1.stl" scale="0.001 0.001 0.001"/>
      </geometry>
      <material name="light_gray"/>
    </visual>
    <collision>
      <origin rpy="0 0 0" xyz="-0.002061 -0.07965 -0.609638"/>
      <geometry>
        <mesh filename="file:///home/lwj/colcon_ws/install/masterHumanoid2025_description/share/masterHumanoid2025_description/meshes/left_upper_frame_1.stl" scale="0.001 0.001 0.001"/>
      </geometry>
    </collision>
  </link>
  <link name="right_upper_frame_1">
    <inertial>
      <origin rpy="0 0 0" xyz="-0.0068947219033479515 3.918892374304983e-06 -0.020909570157323865"/>
      <mass value="0.1555228610526311"/>
      <inertia ixx="0.000126" ixy="1e-06" ixz="-2e-06" iyy="0.000495" iyz="0.0" izz="0.000452"/>
    </inertial>
    <visual>
      <origin rpy="0 0 0" xyz="-0.002061 0.08035 -0.609638"/>
      <geometry>
        <mesh filename="file:///home/lwj/colcon_ws/install/masterHumanoid2025_description/share/masterHumanoid2025_description/meshes/right_upper_frame_1.stl" scale="0.001 0.001 0.001"/>
      </geometry>
      <material name="light_gray"/>
    </visual>
    <collision>
      <origin rpy="0 0 0" xyz="-0.002061 0.08035 -0.609638"/>
      <geometry>
        <mesh filename="file:///home/lwj/colcon_ws/install/masterHumanoid2025_description/share/masterHumanoid2025_description/meshes/right_upper_frame_1.stl" scale="0.001 0.001 0.001"/>
      </geometry>
    </collision>
  </link>
  <link name="left_upper_gearbox_1">
    <inertial>
      <origin rpy="0 0 0" xyz="0.05461317742426483 0.0010494997370183168 -0.02745729931198171"/>
      <mass value="0.75"/>
      <inertia ixx="0.0009" ixy="3.6e-05" ixz="-2.5e-05" iyy="0.00133" iyz="1.8e-05" izz="0.001413"/>
    </inertial>
    <visual>
      <origin rpy="0 0 0" xyz="0.064422 -0.079715 -0.550206"/>
      <geometry>
        <mesh filename="file:///home/lwj/colcon_ws/install/masterHumanoid2025_description/share/masterHumanoid2025_description/meshes/left_upper_gearbox_1.stl" scale="0.001 0.001 0.001"/>
      </geometry>
      <material name="sky_blue"/>
    </visual>
    <collision>
      <origin rpy="0 0 0" xyz="0.064422 -0.079715 -0.550206"/>
      <geometry>
        <mesh filename="file:///home/lwj/colcon_ws/install/masterHumanoid2025_description/share/masterHumanoid2025_description/meshes/left_upper_gearbox_1.stl" scale="0.001 0.001 0.001"/>
      </geometry>
    </collision>
  </link>
  <link name="right_upper_gearbox_1">
    <inertial>
      <origin rpy="0 0 0" xyz="0.05510810569418474 -0.001202909104967953 -0.027501117303870726"/>
      <mass value="0.75"/>
      <inertia ixx="0.0009" ixy="-3.5e-05" ixz="-2.5e-05" iyy="0.00133" iyz="-1.8e-05" izz="0.001413"/>
    </inertial>
    <visual>
      <origin rpy="0 0 0" xyz="0.064422 0.080239 -0.550206"/>
      <geometry>
        <mesh filename="file:///home/lwj/colcon_ws/install/masterHumanoid2025_description/share/masterHumanoid2025_description/meshes/right_upper_gearbox_1.stl" scale="0.001 0.001 0.001"/>
      </geometry>
      <material name="sky_blue"/>
    </visual>
    <collision>
      <origin rpy="0 0 0" xyz="0.064422 0.080239 -0.550206"/>
      <geometry>
        <mesh filename="file:///home/lwj/colcon_ws/install/masterHumanoid2025_description/share/masterHumanoid2025_description/meshes/right_upper_gearbox_1.stl" scale="0.001 0.001 0.001"/>
      </geometry>
    </collision>
  </link>
  <link name="right_middle_leg_1">
    <inertial>
      <origin rpy="0 0 0" xyz="-0.002039057333556183 0.05039566010299555 -0.1716171695275195"/>
      <mass value="0.927"/>
      <inertia ixx="0.005508" ixy="-2e-06" ixz="-0.000154" iyy="0.004327" iyz="-1e-06" izz="0.001626"/>
    </inertial>
    <visual>
      <origin rpy="0 0 0" xyz="-0.026028 0.130854 -0.541945"/>
      <geometry>
        <mesh filename="file:///home/lwj/colcon_ws/install/masterHumanoid2025_description/share/masterHumanoid2025_description/meshes/right_middle_leg_1.stl" scale="0.001 0.001 0.001"/>
      </geometry>
      <material name="mint_green"/>
    </visual>
    <collision>
      <origin rpy="0 0 0" xyz="-0.026028 0.130854 -0.541945"/>
      <geometry>
        <mesh filename="file:///home/lwj/colcon_ws/install/masterHumanoid2025_description/share/masterHumanoid2025_description/meshes/right_middle_leg_1.stl" scale="0.001 0.001 0.001"/>
      </geometry>
    </collision>
  </link>
  <link name="left_middle_leg_1">
    <inertial>
      <origin rpy="0 0 0" xyz="-0.0016744729586776093 -0.050348090773382356 -0.1716351578724804"/>
      <mass value="0.927"/>
      <inertia ixx="0.005509" ixy="-1e-06" ixz="-0.000142" iyy="0.004327" iyz="3e-06" izz="0.001625"/>
    </inertial>
    <visual>
      <origin rpy="0 0 0" xyz="-0.025677 -0.130069 -0.542001"/>
      <geometry>
        <mesh filename="file:///home/lwj/colcon_ws/install/masterHumanoid2025_description/share/masterHumanoid2025_description/meshes/left_middle_leg_1.stl" scale="0.001 0.001 0.001"/>
      </geometry>
      <material name="mint_green"/>
    </visual>
    <collision>
      <origin rpy="0 0 0" xyz="-0.025677 -0.130069 -0.542001"/>
      <geometry>
        <mesh filename="file:///home/lwj/colcon_ws/install/masterHumanoid2025_description/share/masterHumanoid2025_description/meshes/left_middle_leg_1.stl" scale="0.001 0.001 0.001"/>
      </geometry>
    </collision>
  </link>
  <link name="left_lower_leg_1">
    <inertial>
      <origin rpy="0 0 0" xyz="-0.013784998532198027 -0.050405366896745935 -0.08899251108621237"/>
      <mass value="0.715"/>
      <inertia ixx="0.001799" ixy="-1e-06" ixz="-4.7e-05" iyy="0.001164" iyz="0.0" izz="0.000785"/>
    </inertial>
    <visual>
      <origin rpy="0 0 0" xyz="-0.003605 -0.130312 -0.292978"/>
      <geometry>
        <mesh filename="file:///home/lwj/colcon_ws/install/masterHumanoid2025_description/share/masterHumanoid2025_description/meshes/left_lower_leg_1.stl" scale="0.001 0.001 0.001"/>
      </geometry>
      <material name="peach"/>
    </visual>
    <collision>
      <origin rpy="0 0 0" xyz="-0.003605 -0.130312 -0.292978"/>
      <geometry>
        <mesh filename="file:///home/lwj/colcon_ws/install/masterHumanoid2025_description/share/masterHumanoid2025_description/meshes/left_lower_leg_1.stl" scale="0.001 0.001 0.001"/>
      </geometry>
    </collision>
  </link>
  <link name="right_lower_leg_1">
    <inertial>
      <origin rpy="0 0 0" xyz="-0.013637598547290068 0.0504678210058071 -0.08897924378035954"/>
      <mass value="0.715"/>
      <inertia ixx="0.001799" ixy="-1e-06" ixz="-4.7e-05" iyy="0.001164" iyz="-0.0" izz="0.000785"/>
    </inertial>
    <visual>
      <origin rpy="0 0 0" xyz="-0.003213 0.130971 -0.292988"/>
      <geometry>
        <mesh filename="file:///home/lwj/colcon_ws/install/masterHumanoid2025_description/share/masterHumanoid2025_description/meshes/right_lower_leg_1.stl" scale="0.001 0.001 0.001"/>
      </geometry>
      <material name="peach"/>
    </visual>
    <collision>
      <origin rpy="0 0 0" xyz="-0.003213 0.130971 -0.292988"/>
      <geometry>
        <mesh filename="file:///home/lwj/colcon_ws/install/masterHumanoid2025_description/share/masterHumanoid2025_description/meshes/right_lower_leg_1.stl" scale="0.001 0.001 0.001"/>
      </geometry>
    </collision>
  </link>
  <link name="right_lower_gearbox_1">
    <inertial>
      <origin rpy="0 0 0" xyz="-0.031464146139689994 0.051709582806054394 0.025036773942110124"/>
      <mass value="0.75"/>
      <inertia ixx="0.000924" ixy="3.3e-05" ixz="0.000111" iyy="0.00133" iyz="-2.4e-05" izz="0.001389"/>
    </inertial>
    <visual>
      <origin rpy="0 0 0" xyz="0.018569 0.131089 -0.044016"/>
      <geometry>
        <mesh filename="file:///home/lwj/colcon_ws/install/masterHumanoid2025_description/share/masterHumanoid2025_description/meshes/right_lower_gearbox_1.stl" scale="0.001 0.001 0.001"/>
      </geometry>
      <material name="silver"/>
    </visual>
    <collision>
      <origin rpy="0 0 0" xyz="0.018569 0.131089 -0.044016"/>
      <geometry>
        <mesh filename="file:///home/lwj/colcon_ws/install/masterHumanoid2025_description/share/masterHumanoid2025_description/meshes/right_lower_gearbox_1.stl" scale="0.001 0.001 0.001"/>
      </geometry>
    </collision>
  </link>
  <link name="left_lower_gearbox_1">
    <inertial>
      <origin rpy="0 0 0" xyz="-0.03161463163781425 -0.05162366210071047 0.02502425476994688"/>
      <mass value="0.75"/>
      <inertia ixx="0.000924" ixy="-3.2e-05" ixz="0.000111" iyy="0.00133" iyz="2.4e-05" izz="0.001389"/>
    </inertial>
    <visual>
      <origin rpy="0 0 0" xyz="0.018177 -0.130555 -0.044005"/>
      <geometry>
        <mesh filename="file:///home/lwj/colcon_ws/install/masterHumanoid2025_description/share/masterHumanoid2025_description/meshes/left_lower_gearbox_1.stl" scale="0.001 0.001 0.001"/>
      </geometry>
      <material name="silver"/>
    </visual>
    <collision>
      <origin rpy="0 0 0" xyz="0.018177 -0.130555 -0.044005"/>
      <geometry>
        <mesh filename="file:///home/lwj/colcon_ws/install/masterHumanoid2025_description/share/masterHumanoid2025_description/meshes/left_lower_gearbox_1.stl" scale="0.001 0.001 0.001"/>
      </geometry>
    </collision>
  </link>
  <link name="right_foot_1">
    <inertial>
      <origin rpy="0 0 0" xyz="0.06322056024770292 -0.00948657106036395 -0.06587835514287177"/>
      <mass value="0.394"/>
      <inertia ixx="0.002293" ixy="5.1e-05" ixz="0.000807" iyy="0.007731" iyz="-9.3e-05" izz="0.008918"/>
    </inertial>
    <visual>
      <origin rpy="0 0 0" xyz="0.109581 0.080373 -0.051583"/>
      <geometry>
        <mesh filename="file:///home/lwj/colcon_ws/install/masterHumanoid2025_description/share/masterHumanoid2025_description/meshes/right_foot_1.stl" scale="0.001 0.001 0.001"/>
      </geometry>
      <material name="silver"/>
    </visual>
    <collision>
      <origin rpy="0 0 0" xyz="0.109581 0.080373 -0.051583"/>
      <geometry>
        <mesh filename="file:///home/lwj/colcon_ws/install/masterHumanoid2025_description/share/masterHumanoid2025_description/meshes/right_foot_1.stl" scale="0.001 0.001 0.001"/>
      </geometry>
    </collision>
  </link>
  <link name="left_foot_1">
    <inertial>
      <origin rpy="0 0 0" xyz="0.06324664730784718 0.009252948192691707 -0.0658864280055595"/>
      <mass value="0.394"/>
      <inertia ixx="0.002292" ixy="-3.5e-05" ixz="0.000807" iyy="0.007732" iyz="9.1e-05" izz="0.008918"/>
    </inertial>
    <visual>
      <origin rpy="0 0 0" xyz="0.109336 -0.080103 -0.05156"/>
      <geometry>
        <mesh filename="file:///home/lwj/colcon_ws/install/masterHumanoid2025_description/share/masterHumanoid2025_description/meshes/left_foot_1.stl" scale="0.001 0.001 0.001"/>
      </geometry>
      <material name="silver"/>
    </visual>
    <collision>
      <origin rpy="0 0 0" xyz="0.109336 -0.080103 -0.05156"/>
      <geometry>
        <mesh filename="file:///home/lwj/colcon_ws/install/masterHumanoid2025_description/share/masterHumanoid2025_description/meshes/left_foot_1.stl" scale="0.001 0.001 0.001"/>
      </geometry>
    </collision>
  </link>
  <!-- joint 정의부 / 댐핑 계수 마찰 계수 완료 / 조인트 리밋 지정 완료  -->
  <!-- 고관절 요축 DYNAMIXEL_MX_106 -->
  <joint name="rotate_12" type="revolute">
    <origin rpy="0 0 0" xyz="0.002061 0.07965 0.609638"/>
    <parent link="base_link"/>
    <child link="left_upper_frame_1"/>
    <axis xyz="-0.087156 -0.0 -0.996195"/>
    <limit lower="-0.0352816" upper="0.0" effort="10.0" velocity="5.75"/>
    <dynamics damping="0.05" friction="0.1"/>
  </joint>
  <joint name="rotate_13" type="revolute">
    <origin rpy="0 0 0" xyz="0.002061 -0.08035 0.609638"/>
    <parent link="base_link"/>
    <child link="right_upper_frame_1"/>
    <axis xyz="-0.087156 -0.0 -0.996195"/>
    <limit lower="0.0" upper="0.0352816" effort="10.0" velocity="5.75"/>
    <dynamics damping="0.05" friction="0.1"/>
  </joint>
  <!-- 고관절 롤축 GEAR_BOX  -->
  <joint name="rotate_10" type="revolute">
    <origin rpy="0 0 0" xyz="-0.066483 6.5e-05 -0.059432"/>
    <parent link="left_upper_frame_1"/>
    <child link="left_upper_gearbox_1"/>
    <axis xyz="-0.996194 0.001062 0.087156"/>
    <limit lower="-0.0972665" upper="-0.0772665" effort="15.0" velocity="3.84"/>
    <dynamics damping="0.1125" friction="0.15"/>
  </joint>
  <joint name="rotate_11" type="revolute">
    <origin rpy="0 0 0" xyz="-0.066483 0.000111 -0.059432"/>
    <parent link="right_upper_frame_1"/>
    <child link="right_upper_gearbox_1"/>
    <axis xyz="-0.996193 0.001816 0.087156"/>
    <limit lower="0.0772665" upper="0.0972665" effort="15.0" velocity="3.84"/>
    <dynamics damping="0.1125" friction="0.15"/>
  </joint>
  <!-- 고관절 피치축 DUAL_MOTOR -->
  <joint name="rotate_15" type="revolute">
    <origin rpy="0 0 0" xyz="0.09045 -0.050615 -0.008261"/>
    <parent link="right_upper_gearbox_1"/>
    <child link="right_middle_leg_1"/>
    <axis xyz="-0.001768 -0.999998 0.000629"/>
    <limit lower="0.377359" upper="0.667282" effort="20.0" velocity="5.76"/>
    <dynamics damping="0.11" friction="0.22"/>
  </joint>
  <joint name="rotate_14" type="revolute">
    <origin rpy="0 0 0" xyz="0.090099 0.050354 -0.008205"/>
    <parent link="left_upper_gearbox_1"/>
    <child link="left_middle_leg_1"/>
    <axis xyz="0.001142 0.999999 0.000876"/>
    <limit lower="-0.667282" upper="-0.377359" effort="20.0" velocity="5.76"/>
    <dynamics damping="0.11" friction="0.22"/>
  </joint>
  <!-- 무릎관절 피치축 DUAL_MOTOR -->
  <joint name="rotate_16" type="revolute">
    <origin rpy="0 0 0" xyz="-0.022072 0.000243 -0.249023"/>
    <parent link="left_middle_leg_1"/>
    <child link="left_lower_leg_1"/>
    <axis xyz="0.001142 0.999999 0.000876"/>
    <limit lower="0.739379" upper="1.07532" effort="20.0" velocity="5.76"/>
    <dynamics damping="0.11" friction="0.22"/>
  </joint>
  <joint name="rotate_17" type="revolute">
    <origin rpy="0 0 0" xyz="-0.022815 -0.000117 -0.248957"/>
    <parent link="right_middle_leg_1"/>
    <child link="right_lower_leg_1"/>
    <axis xyz="-0.001768 -0.999998 0.000629"/>
    <limit lower="-1.07532" upper="-0.739379" effort="20.0" velocity="5.76"/>
    <dynamics damping="0.11" friction="0.22"/>
  </joint>
  <!-- 발목 관절 피치축 DUAL_MOTOR / 축 반전처리 완료 -->
  <joint name="rotate_19" type="revolute">
    <origin rpy="0 0 0" xyz="-0.021782 -0.000118 -0.248972"/>
    <parent link="right_lower_leg_1"/>
    <child link="right_lower_gearbox_1"/>
    <axis xyz="-0.001768 -0.999998 0.000629"/>
    <limit lower="-0.306796" upper="-0.543029" effort="20.0" velocity="5.76"/>
    <dynamics damping="0.11" friction="0.22"/>
  </joint>
  <joint name="rotate_18" type="revolute">
    <origin rpy="0 0 0" xyz="-0.021782 0.000243 -0.248973"/>
    <parent link="left_lower_leg_1"/>
    <child link="left_lower_gearbox_1"/>
    <axis xyz="0.001142 0.999999 0.000876"/>
    <limit lower="-0.543029" upper="-0.306796" effort="20.0" velocity="5.76"/>
    <dynamics damping="0.11" friction="0.22"/>
  </joint>
  <!-- 발목 관절 롤축  GEAR_BOX -->
  <joint name="rotate_21" type="revolute">
    <origin rpy="0 0 0" xyz="-0.091012 0.050716 0.007567"/>
    <parent link="right_lower_gearbox_1"/>
    <child link="right_foot_1"/>
    <axis xyz="-0.996193 0.001816 0.087156"/>
    <limit lower="-0.0972665" upper="-0.0772665" effort="6.0" velocity="6.6"/>
    <dynamics damping="0.1125" friction="0.15"/>
  </joint>
  <joint name="rotate_20" type="revolute">
    <origin rpy="0 0 0" xyz="-0.091159 -0.050452 0.007555"/>
    <parent link="left_lower_gearbox_1"/>
    <child link="left_foot_1"/>
    <axis xyz="-0.996194 0.001062 0.087156"/>
    <limit lower="0.0772665" upper="0.0972665" effort="6.0" velocity="6.6"/>
    <dynamics damping="0.1125" friction="0.15"/>
  </joint>
</robot>
