<?xml version="1.0" ?>
<robot name="masterHumanoid2025" xmlns:xacro="http://www.ros.org/wiki/xacro">

<xacro:include filename="$(find masterHumanoid2025_description)/urdf/materials.xacro" />
<xacro:include filename="$(find masterHumanoid2025_description)/urdf/masterHumanoid2025.trans" />
<xacro:include filename="$(find masterHumanoid2025_description)/urdf/masterHumanoid2025.gazebo" />
<link name="base_link">
  <inertial>
    <origin xyz="-0.0019277625580420743 -0.0002828648876733997 0.690502612360238" rpy="0 0 0"/>
    <mass value="5.614608211157563"/>
    <inertia ixx="0.296093" iyy="0.167039" izz="0.152631" ixy="0.000112" iyz="-0.000108" ixz="0.001772"/>
  </inertial>
  <visual>
    <origin xyz="0 0 0" rpy="0 0 0"/>
    <geometry>
      <mesh filename="file://$(find masterHumanoid2025_description)/meshes/base_link.stl" scale="0.001 0.001 0.001"/>
    </geometry>
    <material name="silver"/>
  </visual>
  <collision>
    <origin xyz="0 0 0" rpy="0 0 0"/>
    <geometry>
      <mesh filename="file://$(find masterHumanoid2025_description)/meshes/base_link.stl" scale="0.001 0.001 0.001"/>
    </geometry>
  </collision>
</link>

<link name="left_upper_frame_1">
  <inertial>
    <origin xyz="-0.005046700831779199 1.0557817920323065e-05 -0.02143088061471432" rpy="0 0 0"/>
    <mass value="0.1555228615666778"/>
    <inertia ixx="0.000129" iyy="0.000495" izz="0.000449" ixy="0.0" iyz="0.0" ixz="-3e-05"/>
  </inertial>
  <visual>
    <origin xyz="0.009035 -0.07965 -0.648137" rpy="0 0 0"/>
    <geometry>
      <mesh filename="file://$(find masterHumanoid2025_description)/meshes/left_upper_frame_1.stl" scale="0.001 0.001 0.001"/>
    </geometry>
    <material name="silver"/>
  </visual>
  <collision>
    <origin xyz="0.009035 -0.07965 -0.648137" rpy="0 0 0"/>
    <geometry>
      <mesh filename="file://$(find masterHumanoid2025_description)/meshes/left_upper_frame_1.stl" scale="0.001 0.001 0.001"/>
    </geometry>
  </collision>
</link>

<link name="right_upper_frame_1">
  <inertial>
    <origin xyz="-0.0050467103826035645 3.918892784643413e-06 -0.021430880698611654" rpy="0 0 0"/>
    <mass value="0.1555228610526311"/>
    <inertia ixx="0.000129" iyy="0.000495" izz="0.000449" ixy="1e-06" iyz="0.0" ixz="-3e-05"/>
  </inertial>
  <visual>
    <origin xyz="0.009035 0.08035 -0.648137" rpy="0 0 0"/>
    <geometry>
      <mesh filename="file://$(find masterHumanoid2025_description)/meshes/right_upper_frame_1.stl" scale="0.001 0.001 0.001"/>
    </geometry>
    <material name="silver"/>
  </visual>
  <collision>
    <origin xyz="0.009035 0.08035 -0.648137" rpy="0 0 0"/>
    <geometry>
      <mesh filename="file://$(find masterHumanoid2025_description)/meshes/right_upper_frame_1.stl" scale="0.001 0.001 0.001"/>
    </geometry>
  </collision>
</link>

<link name="left_upper_gearbox_1">
  <inertial>
    <origin xyz="0.05679763300573742 0.0010494997385310512 -0.02259314565567294" rpy="0 0 0"/>
    <mass value="0.7539590478154932"/>
    <inertia ixx="0.000908" iyy="0.00133" izz="0.001405" ixy="3.5e-05" iyz="2.1e-05" ixz="-6.9e-05"/>
  </inertial>
  <visual>
    <origin xyz="0.070085 -0.079715 -0.583137" rpy="0 0 0"/>
    <geometry>
      <mesh filename="file://$(find masterHumanoid2025_description)/meshes/left_upper_gearbox_1.stl" scale="0.001 0.001 0.001"/>
    </geometry>
    <material name="silver"/>
  </visual>
  <collision>
    <origin xyz="0.070085 -0.079715 -0.583137" rpy="0 0 0"/>
    <geometry>
      <mesh filename="file://$(find masterHumanoid2025_description)/meshes/left_upper_gearbox_1.stl" scale="0.001 0.001 0.001"/>
    </geometry>
  </collision>
</link>

<link name="right_upper_gearbox_1">
  <inertial>
    <origin xyz="0.057294496913915735 -0.0012029091034558848 -0.022593661068604054" rpy="0 0 0"/>
    <mass value="0.7539598848625294"/>
    <inertia ixx="0.000908" iyy="0.00133" izz="0.001405" ixy="-3.3e-05" iyz="-2.1e-05" ixz="-6.9e-05"/>
  </inertial>
  <visual>
    <origin xyz="0.070085 0.080239 -0.583137" rpy="0 0 0"/>
    <geometry>
      <mesh filename="file://$(find masterHumanoid2025_description)/meshes/right_upper_gearbox_1.stl" scale="0.001 0.001 0.001"/>
    </geometry>
    <material name="silver"/>
  </visual>
  <collision>
    <origin xyz="0.070085 0.080239 -0.583137" rpy="0 0 0"/>
    <geometry>
      <mesh filename="file://$(find masterHumanoid2025_description)/meshes/right_upper_gearbox_1.stl" scale="0.001 0.001 0.001"/>
    </geometry>
  </collision>
</link>

<link name="right_middle_leg_1">
  <inertial>
    <origin xyz="0.0129261417013413 0.0503956601070247 -0.17114233911271742" rpy="0 0 0"/>
    <mass value="1.077312188551498"/>
    <inertia ixx="0.005505" iyy="0.004327" izz="0.001628" ixy="-2e-06" iyz="-2e-06" ixz="0.000186"/>
  </inertial>
  <visual>
    <origin xyz="-0.02074 0.130854 -0.582791" rpy="0 0 0"/>
    <geometry>
      <mesh filename="file://$(find masterHumanoid2025_description)/meshes/right_middle_leg_1.stl" scale="0.001 0.001 0.001"/>
    </geometry>
    <material name="silver"/>
  </visual>
  <collision>
    <origin xyz="-0.02074 0.130854 -0.582791" rpy="0 0 0"/>
    <geometry>
      <mesh filename="file://$(find masterHumanoid2025_description)/meshes/right_middle_leg_1.stl" scale="0.001 0.001 0.001"/>
    </geometry>
  </collision>
</link>

<link name="left_middle_leg_1">
  <inertial>
    <origin xyz="0.013291361449427885 -0.05034809076935265 -0.17112828814454834" rpy="0 0 0"/>
    <mass value="1.077312207009041"/>
    <inertia ixx="0.005504" iyy="0.004327" izz="0.00163" ixy="-1e-06" iyz="2e-06" ixz="0.000197"/>
  </inertial>
  <visual>
    <origin xyz="-0.020385 -0.130069 -0.582816" rpy="0 0 0"/>
    <geometry>
      <mesh filename="file://$(find masterHumanoid2025_description)/meshes/left_middle_leg_1.stl" scale="0.001 0.001 0.001"/>
    </geometry>
    <material name="silver"/>
  </visual>
  <collision>
    <origin xyz="-0.020385 -0.130069 -0.582816" rpy="0 0 0"/>
    <geometry>
      <mesh filename="file://$(find masterHumanoid2025_description)/meshes/left_middle_leg_1.stl" scale="0.001 0.001 0.001"/>
    </geometry>
  </collision>
</link>

<link name="left_lower_leg_1">
  <inertial>
    <origin xyz="-0.005976086031339919 -0.050405366889918674 -0.08985471728805111" rpy="0 0 0"/>
    <mass value="0.5227872807967037"/>
    <inertia ixx="0.001799" iyy="0.001164" izz="0.000784" ixy="-1e-06" iyz="0.0" ixz="4.2e-05"/>
  </inertial>
  <visual>
    <origin xyz="-0.020101 -0.130312 -0.332816" rpy="0 0 0"/>
    <geometry>
      <mesh filename="file://$(find masterHumanoid2025_description)/meshes/left_lower_leg_1.stl" scale="0.001 0.001 0.001"/>
    </geometry>
    <material name="silver"/>
  </visual>
  <collision>
    <origin xyz="-0.020101 -0.130312 -0.332816" rpy="0 0 0"/>
    <geometry>
      <mesh filename="file://$(find masterHumanoid2025_description)/meshes/left_lower_leg_1.stl" scale="0.001 0.001 0.001"/>
    </geometry>
  </collision>
</link>

<link name="right_lower_leg_1">
  <inertial>
    <origin xyz="-0.005830783148732369 0.050467821012633265 -0.08982985681998587" rpy="0 0 0"/>
    <mass value="0.5227872807963939"/>
    <inertia ixx="0.001799" iyy="0.001164" izz="0.000784" ixy="-1e-06" iyz="-0.0" ixz="4.2e-05"/>
  </inertial>
  <visual>
    <origin xyz="-0.01971 0.130971 -0.332793" rpy="0 0 0"/>
    <geometry>
      <mesh filename="file://$(find masterHumanoid2025_description)/meshes/right_lower_leg_1.stl" scale="0.001 0.001 0.001"/>
    </geometry>
    <material name="silver"/>
  </visual>
  <collision>
    <origin xyz="-0.01971 0.130971 -0.332793" rpy="0 0 0"/>
    <geometry>
      <mesh filename="file://$(find masterHumanoid2025_description)/meshes/right_lower_leg_1.stl" scale="0.001 0.001 0.001"/>
    </geometry>
  </collision>
</link>

<link name="left_lower_gearbox_1">
  <inertial>
    <origin xyz="-0.033526419385759954 0.05170958281515828 0.022199596774821334" rpy="0 0 0"/>
    <mass value="0.753959453663333"/>
    <inertia ixx="0.000908" iyy="0.00133" izz="0.001405" ixy="3.5e-05" iyz="-2.1e-05" ixz="6.9e-05"/>
  </inertial>
  <visual>
    <origin xyz="-0.01971 0.131089 -0.082869" rpy="0 0 0"/>
    <geometry>
      <mesh filename="file://$(find masterHumanoid2025_description)/meshes/left_lower_gearbox_1.stl" scale="0.001 0.001 0.001"/>
    </geometry>
    <material name="silver"/>
  </visual>
  <collision>
    <origin xyz="-0.01971 0.131089 -0.082869" rpy="0 0 0"/>
    <geometry>
      <mesh filename="file://$(find masterHumanoid2025_description)/meshes/left_lower_gearbox_1.stl" scale="0.001 0.001 0.001"/>
    </geometry>
  </collision>
</link>

<link name="right_lower_gearbox_1">
  <inertial>
    <origin xyz="-0.03367477408867826 -0.05162366209160814 0.022174216478641956" rpy="0 0 0"/>
    <mass value="0.7539594232725966"/>
    <inertia ixx="0.000908" iyy="0.00133" izz="0.001405" ixy="-3.4e-05" iyz="2.1e-05" ixz="6.9e-05"/>
  </inertial>
  <visual>
    <origin xyz="-0.020101 -0.130555 -0.082892" rpy="0 0 0"/>
    <geometry>
      <mesh filename="file://$(find masterHumanoid2025_description)/meshes/right_lower_gearbox_1.stl" scale="0.001 0.001 0.001"/>
    </geometry>
    <material name="silver"/>
  </visual>
  <collision>
    <origin xyz="-0.020101 -0.130555 -0.082892" rpy="0 0 0"/>
    <geometry>
      <mesh filename="file://$(find masterHumanoid2025_description)/meshes/right_lower_gearbox_1.stl" scale="0.001 0.001 0.001"/>
    </geometry>
  </collision>
</link>

<link name="left_foot_1">
  <inertial>
    <origin xyz="0.06872157934204118 -0.009486571049873826 -0.06011727006259174" rpy="0 0 0"/>
    <mass value="1.3311575432838623"/>
    <inertia ixx="0.002203" iyy="0.007731" izz="0.009008" ixy="5.9e-05" iyz="-8.8e-05" ixz="0.000219"/>
  </inertial>
  <visual>
    <origin xyz="0.071615 0.080373 -0.082475" rpy="0 0 0"/>
    <geometry>
      <mesh filename="file://$(find masterHumanoid2025_description)/meshes/left_foot_1.stl" scale="0.001 0.001 0.001"/>
    </geometry>
    <material name="silver"/>
  </visual>
  <collision>
    <origin xyz="0.071615 0.080373 -0.082475" rpy="0 0 0"/>
    <geometry>
      <mesh filename="file://$(find masterHumanoid2025_description)/meshes/left_foot_1.stl" scale="0.001 0.001 0.001"/>
    </geometry>
  </collision>
</link>

<link name="right_foot_1">
  <inertial>
    <origin xyz="0.06874834301237638 0.009252948203182856 -0.060122597886593396" rpy="0 0 0"/>
    <mass value="1.331157749098713"/>
    <inertia ixx="0.002203" iyy="0.007732" izz="0.009008" ixy="-4.3e-05" iyz="8.8e-05" ixz="0.000219"/>
  </inertial>
  <visual>
    <origin xyz="0.071369 -0.080103 -0.082473" rpy="0 0 0"/>
    <geometry>
      <mesh filename="file://$(find masterHumanoid2025_description)/meshes/right_foot_1.stl" scale="0.001 0.001 0.001"/>
    </geometry>
    <material name="silver"/>
  </visual>
  <collision>
    <origin xyz="0.071369 -0.080103 -0.082473" rpy="0 0 0"/>
    <geometry>
      <mesh filename="file://$(find masterHumanoid2025_description)/meshes/right_foot_1.stl" scale="0.001 0.001 0.001"/>
    </geometry>
  </collision>
</link>

<joint name="rotate_12" type="continuous">
  <origin xyz="-0.009035 0.07965 0.648137" rpy="0 0 0"/>
  <parent link="base_link"/>
  <child link="left_upper_frame_1"/>
  <axis xyz="0.0 0.0 -1.0"/>
</joint>

<joint name="rotate_13" type="continuous">
  <origin xyz="-0.009035 -0.08035 0.648137" rpy="0 0 0"/>
  <parent link="base_link"/>
  <child link="right_upper_frame_1"/>
  <axis xyz="0.0 0.0 -1.0"/>
</joint>

<joint name="rotate_10" type="continuous">
  <origin xyz="-0.06105 6.5e-05 -0.065" rpy="0 0 0"/>
  <parent link="left_upper_frame_1"/>
  <child link="left_upper_gearbox_1"/>
  <axis xyz="-0.999999 0.001062 -0.0"/>
</joint>

<joint name="rotate_11" type="continuous">
  <origin xyz="-0.06105 0.000111 -0.065" rpy="0 0 0"/>
  <parent link="right_upper_frame_1"/>
  <child link="right_upper_gearbox_1"/>
  <axis xyz="-0.999998 0.001816 -0.0"/>
</joint>

<joint name="rotate_15" type="continuous">
  <origin xyz="0.090825 -0.050615 -0.000346" rpy="0 0 0"/>
  <parent link="right_upper_gearbox_1"/>
  <child link="right_middle_leg_1"/>
  <axis xyz="-0.001816 -0.999998 0.000473"/>
</joint>

<joint name="rotate_14" type="continuous">
  <origin xyz="0.09047 0.050354 -0.000321" rpy="0 0 0"/>
  <parent link="left_upper_gearbox_1"/>
  <child link="left_middle_leg_1"/>
  <axis xyz="0.001062 0.999999 0.000972"/>
</joint>

<joint name="rotate_16" type="continuous">
  <origin xyz="-0.000284 0.000243 -0.25" rpy="0 0 0"/>
  <parent link="left_middle_leg_1"/>
  <child link="left_lower_leg_1"/>
  <axis xyz="0.001062 0.999999 0.000972"/>
</joint>

<joint name="rotate_17" type="continuous">
  <origin xyz="-0.00103 -0.000117 -0.249998" rpy="0 0 0"/>
  <parent link="right_middle_leg_1"/>
  <child link="right_lower_leg_1"/>
  <axis xyz="-0.001816 -0.999998 0.000473"/>
</joint>

<joint name="rotate_19" type="continuous">
  <origin xyz="0.0 -0.000118 -0.249924" rpy="0 0 0"/>
  <parent link="right_lower_leg_1"/>
  <child link="left_lower_gearbox_1"/>
  <axis xyz="-0.001816 -0.999998 0.000473"/>
</joint>

<joint name="rotate_18" type="continuous">
  <origin xyz="0.0 0.000243 -0.249924" rpy="0 0 0"/>
  <parent link="left_lower_leg_1"/>
  <child link="right_lower_gearbox_1"/>
  <axis xyz="0.001062 0.999999 0.000972"/>
</joint>

<joint name="rotate_21" type="continuous">
  <origin xyz="-0.091325 0.050716 -0.000394" rpy="0 0 0"/>
  <parent link="left_lower_gearbox_1"/>
  <child link="left_foot_1"/>
  <axis xyz="-0.999998 0.001816 -0.0"/>
</joint>

<joint name="rotate_20" type="continuous">
  <origin xyz="-0.09147 -0.050452 -0.000419" rpy="0 0 0"/>
  <parent link="right_lower_gearbox_1"/>
  <child link="right_foot_1"/>
  <axis xyz="-0.999999 0.001062 0.0"/>
</joint>

</robot>
