<?xml version="1.0" ?>
<robot name="offset_IEEE_2025" xmlns:xacro="http://www.ros.org/wiki/xacro">

<xacro:include filename="$(find offset_IEEE_2025_description)/urdf/materials.xacro" />
<xacro:include filename="$(find offset_IEEE_2025_description)/urdf/offset_IEEE_2025.trans" />
<xacro:include filename="$(find offset_IEEE_2025_description)/urdf/offset_IEEE_2025.gazebo" />
<link name="base_link">
  <inertial>
    <origin xyz="0.014064006321208921 1.9983490169064312e-05 0.6527907555630458" rpy="0 0 0"/>
    <mass value="5.614608211157563"/>
    <inertia ixx="0.295311" iyy="0.167039" izz="0.153413" ixy="0.000102" iyz="-0.000117" ixz="-0.010711"/>
  </inertial>
  <visual>
    <origin xyz="0 0 0" rpy="0 0 0"/>
    <geometry>
      <mesh filename="file://$(find offset_IEEE_2025_description)/meshes/base_link.stl" scale="0.001 0.001 0.001"/>
    </geometry>
    <material name="silver"/>
  </visual>
  <collision>
    <origin xyz="0 0 0" rpy="0 0 0"/>
    <geometry>
      <mesh filename="file://$(find offset_IEEE_2025_description)/meshes/base_link.stl" scale="0.001 0.001 0.001"/>
    </geometry>
  </collision>
</link>

<link name="left_upper_frame_1">
  <inertial>
    <origin xyz="-0.006894913278008051 1.0406194705353533e-05 -0.020909686979229014" rpy="0 0 0"/>
    <mass value="0.15552286156667774"/>
    <inertia ixx="0.000126" iyy="0.000495" izz="0.000452" ixy="0.0" iyz="-0.0" ixz="-2e-06"/>
  </inertial>
  <visual>
    <origin xyz="-0.003291 -0.079953 -0.611206" rpy="0 0 0"/>
    <geometry>
      <mesh filename="file://$(find offset_IEEE_2025_description)/meshes/left_upper_frame_1.stl" scale="0.001 0.001 0.001"/>
    </geometry>
    <material name="silver"/>
  </visual>
  <collision>
    <origin xyz="-0.003291 -0.079953 -0.611206" rpy="0 0 0"/>
    <geometry>
      <mesh filename="file://$(find offset_IEEE_2025_description)/meshes/left_upper_frame_1.stl" scale="0.001 0.001 0.001"/>
    </geometry>
  </collision>
</link>

<link name="right_upper_frame_1">
  <inertial>
    <origin xyz="-0.006894922799685279 3.76726957287965e-06 -0.020909686227724267" rpy="0 0 0"/>
    <mass value="0.1555228610526311"/>
    <inertia ixx="0.000126" iyy="0.000495" izz="0.000452" ixy="1e-06" iyz="0.0" ixz="-2e-06"/>
  </inertial>
  <visual>
    <origin xyz="-0.003291 0.080047 -0.611206" rpy="0 0 0"/>
    <geometry>
      <mesh filename="file://$(find offset_IEEE_2025_description)/meshes/right_upper_frame_1.stl" scale="0.001 0.001 0.001"/>
    </geometry>
    <material name="silver"/>
  </visual>
  <collision>
    <origin xyz="-0.003291 0.080047 -0.611206" rpy="0 0 0"/>
    <geometry>
      <mesh filename="file://$(find offset_IEEE_2025_description)/meshes/right_upper_frame_1.stl" scale="0.001 0.001 0.001"/>
    </geometry>
  </collision>
</link>

<link name="left_upper_gearbox_1">
  <inertial>
    <origin xyz="0.0546129765279295 0.00104934811421116 -0.02745741538238644" rpy="0 0 0"/>
    <mass value="0.7539590478154929"/>
    <inertia ixx="0.0009" iyy="0.00133" izz="0.001413" ixy="3.6e-05" iyz="1.8e-05" ixz="-2.5e-05"/>
  </inertial>
  <visual>
    <origin xyz="0.063192 -0.080018 -0.551774" rpy="0 0 0"/>
    <geometry>
      <mesh filename="file://$(find offset_IEEE_2025_description)/meshes/left_upper_gearbox_1.stl" scale="0.001 0.001 0.001"/>
    </geometry>
    <material name="silver"/>
  </visual>
  <collision>
    <origin xyz="0.063192 -0.080018 -0.551774" rpy="0 0 0"/>
    <geometry>
      <mesh filename="file://$(find offset_IEEE_2025_description)/meshes/left_upper_gearbox_1.stl" scale="0.001 0.001 0.001"/>
    </geometry>
  </collision>
</link>

<link name="right_upper_gearbox_1">
  <inertial>
    <origin xyz="0.05510790479784956 -0.0012030607277748323 -0.02750123337426902" rpy="0 0 0"/>
    <mass value="0.7539598848625293"/>
    <inertia ixx="0.0009" iyy="0.00133" izz="0.001413" ixy="-3.5e-05" iyz="-1.8e-05" ixz="-2.5e-05"/>
  </inertial>
  <visual>
    <origin xyz="0.063192 0.079936 -0.551774" rpy="0 0 0"/>
    <geometry>
      <mesh filename="file://$(find offset_IEEE_2025_description)/meshes/right_upper_gearbox_1.stl" scale="0.001 0.001 0.001"/>
    </geometry>
    <material name="silver"/>
  </visual>
  <collision>
    <origin xyz="0.063192 0.079936 -0.551774" rpy="0 0 0"/>
    <geometry>
      <mesh filename="file://$(find offset_IEEE_2025_description)/meshes/right_upper_gearbox_1.stl" scale="0.001 0.001 0.001"/>
    </geometry>
  </collision>
</link>

<link name="right_middle_leg_1">
  <inertial>
    <origin xyz="-0.0020392582298967878 0.05039650848018605 -0.17161728559791845" rpy="0 0 0"/>
    <mass value="1.077312188551498"/>
    <inertia ixx="0.005508" iyy="0.004327" izz="0.001626" ixy="-2e-06" iyz="-1e-06" ixz="-0.000154"/>
  </inertial>
  <visual>
    <origin xyz="-0.027258 0.130552 -0.543513" rpy="0 0 0"/>
    <geometry>
      <mesh filename="file://$(find offset_IEEE_2025_description)/meshes/right_middle_leg_1.stl" scale="0.001 0.001 0.001"/>
    </geometry>
    <material name="silver"/>
  </visual>
  <collision>
    <origin xyz="-0.027258 0.130552 -0.543513" rpy="0 0 0"/>
    <geometry>
      <mesh filename="file://$(find offset_IEEE_2025_description)/meshes/right_middle_leg_1.stl" scale="0.001 0.001 0.001"/>
    </geometry>
  </collision>
</link>

<link name="left_middle_leg_1">
  <inertial>
    <origin xyz="-0.0016746738550164376 -0.05034824239619155 -0.17163527394288253" rpy="0 0 0"/>
    <mass value="1.077312207009042"/>
    <inertia ixx="0.005509" iyy="0.004327" izz="0.001625" ixy="-1e-06" iyz="3e-06" ixz="-0.000142"/>
  </inertial>
  <visual>
    <origin xyz="-0.026907 -0.130372 -0.543569" rpy="0 0 0"/>
    <geometry>
      <mesh filename="file://$(find offset_IEEE_2025_description)/meshes/left_middle_leg_1.stl" scale="0.001 0.001 0.001"/>
    </geometry>
    <material name="silver"/>
  </visual>
  <collision>
    <origin xyz="-0.026907 -0.130372 -0.543569" rpy="0 0 0"/>
    <geometry>
      <mesh filename="file://$(find offset_IEEE_2025_description)/meshes/left_middle_leg_1.stl" scale="0.001 0.001 0.001"/>
    </geometry>
  </collision>
</link>

<link name="left_lower_leg_1">
  <inertial>
    <origin xyz="-0.013785199428538522 -0.05040551851956085 -0.0889916271566169" rpy="0 0 0"/>
    <mass value="0.5227872807967039"/>
    <inertia ixx="0.001799" iyy="0.001164" izz="0.000785" ixy="-1e-06" iyz="0.0" ixz="-4.7e-05"/>
  </inertial>
  <visual>
    <origin xyz="-0.004835 -0.130615 -0.294545" rpy="0 0 0"/>
    <geometry>
      <mesh filename="file://$(find offset_IEEE_2025_description)/meshes/left_lower_leg_1.stl" scale="0.001 0.001 0.001"/>
    </geometry>
    <material name="silver"/>
  </visual>
  <collision>
    <origin xyz="-0.004835 -0.130615 -0.294545" rpy="0 0 0"/>
    <geometry>
      <mesh filename="file://$(find offset_IEEE_2025_description)/meshes/left_lower_leg_1.stl" scale="0.001 0.001 0.001"/>
    </geometry>
  </collision>
</link>

<link name="right_lower_leg_1">
  <inertial>
    <origin xyz="-0.013637799443630187 0.05046766938299317 -0.08897935985075783" rpy="0 0 0"/>
    <mass value="0.5227872807963939"/>
    <inertia ixx="0.001799" iyy="0.001164" izz="0.000785" ixy="-1e-06" iyz="-0.0" ixz="-4.7e-05"/>
  </inertial>
  <visual>
    <origin xyz="-0.004443 0.130668 -0.294556" rpy="0 0 0"/>
    <geometry>
      <mesh filename="file://$(find offset_IEEE_2025_description)/meshes/right_lower_leg_1.stl" scale="0.001 0.001 0.001"/>
    </geometry>
    <material name="silver"/>
  </visual>
  <collision>
    <origin xyz="-0.004443 0.130668 -0.294556" rpy="0 0 0"/>
    <geometry>
      <mesh filename="file://$(find offset_IEEE_2025_description)/meshes/right_lower_leg_1.stl" scale="0.001 0.001 0.001"/>
    </geometry>
  </collision>
</link>

<link name="left_lower_gearbox_1">
  <inertial>
    <origin xyz="-0.031464347036029655 0.051709431183236926 0.02503765787171218" rpy="0 0 0"/>
    <mass value="0.7539594536633326"/>
    <inertia ixx="0.000924" iyy="0.00133" izz="0.001389" ixy="3.3e-05" iyz="-2.4e-05" ixz="0.000111"/>
  </inertial>
  <visual>
    <origin xyz="0.017339 0.130786 -0.045583" rpy="0 0 0"/>
    <geometry>
      <mesh filename="file://$(find offset_IEEE_2025_description)/meshes/left_lower_gearbox_1.stl" scale="0.001 0.001 0.001"/>
    </geometry>
    <material name="silver"/>
  </visual>
  <collision>
    <origin xyz="0.017339 0.130786 -0.045583" rpy="0 0 0"/>
    <geometry>
      <mesh filename="file://$(find offset_IEEE_2025_description)/meshes/left_lower_gearbox_1.stl" scale="0.001 0.001 0.001"/>
    </geometry>
  </collision>
</link>

<link name="right_lower_gearbox_1">
  <inertial>
    <origin xyz="-0.03161483253415551 -0.05162381372353296 0.025024138699542786" rpy="0 0 0"/>
    <mass value="0.7539594232725968"/>
    <inertia ixx="0.000924" iyy="0.00133" izz="0.001389" ixy="-3.2e-05" iyz="2.4e-05" ixz="0.000111"/>
  </inertial>
  <visual>
    <origin xyz="0.016947 -0.130858 -0.045573" rpy="0 0 0"/>
    <geometry>
      <mesh filename="file://$(find offset_IEEE_2025_description)/meshes/right_lower_gearbox_1.stl" scale="0.001 0.001 0.001"/>
    </geometry>
    <material name="silver"/>
  </visual>
  <collision>
    <origin xyz="0.016947 -0.130858 -0.045573" rpy="0 0 0"/>
    <geometry>
      <mesh filename="file://$(find offset_IEEE_2025_description)/meshes/right_lower_gearbox_1.stl" scale="0.001 0.001 0.001"/>
    </geometry>
  </collision>
</link>

<link name="left_foot_1">
  <inertial>
    <origin xyz="0.06322035935135747 -0.009486722683184678 -0.06587847121326908" rpy="0 0 0"/>
    <mass value="1.3311575432838632"/>
    <inertia ixx="0.002293" iyy="0.007731" izz="0.008918" ixy="5.1e-05" iyz="-9.3e-05" ixz="0.000807"/>
  </inertial>
  <visual>
    <origin xyz="0.108351 0.08007 -0.053151" rpy="0 0 0"/>
    <geometry>
      <mesh filename="file://$(find offset_IEEE_2025_description)/meshes/left_foot_1.stl" scale="0.001 0.001 0.001"/>
    </geometry>
    <material name="silver"/>
  </visual>
  <collision>
    <origin xyz="0.108351 0.08007 -0.053151" rpy="0 0 0"/>
    <geometry>
      <mesh filename="file://$(find offset_IEEE_2025_description)/meshes/left_foot_1.stl" scale="0.001 0.001 0.001"/>
    </geometry>
  </collision>
</link>

<link name="right_foot_1">
  <inertial>
    <origin xyz="0.06324744641150522 0.009252796569869645 -0.0658855440759635" rpy="0 0 0"/>
    <mass value="1.331157749098712"/>
    <inertia ixx="0.002292" iyy="0.007732" izz="0.008918" ixy="-3.5e-05" iyz="9.1e-05" ixz="0.000807"/>
  </inertial>
  <visual>
    <origin xyz="0.108107 -0.080406 -0.053127" rpy="0 0 0"/>
    <geometry>
      <mesh filename="file://$(find offset_IEEE_2025_description)/meshes/right_foot_1.stl" scale="0.001 0.001 0.001"/>
    </geometry>
    <material name="silver"/>
  </visual>
  <collision>
    <origin xyz="0.108107 -0.080406 -0.053127" rpy="0 0 0"/>
    <geometry>
      <mesh filename="file://$(find offset_IEEE_2025_description)/meshes/right_foot_1.stl" scale="0.001 0.001 0.001"/>
    </geometry>
  </collision>
</link>

<joint name="rotate_12" type="continuous">
  <origin xyz="0.003291 0.079953 0.611206" rpy="0 0 0"/>
  <parent link="base_link"/>
  <child link="left_upper_frame_1"/>
  <axis xyz="-0.087156 -0.0 -0.996195"/>
</joint>

<joint name="rotate_13" type="continuous">
  <origin xyz="0.003291 -0.080047 0.611206" rpy="0 0 0"/>
  <parent link="base_link"/>
  <child link="right_upper_frame_1"/>
  <axis xyz="-0.087156 -0.0 -0.996195"/>
</joint>

<joint name="rotate_10" type="continuous">
  <origin xyz="-0.066483 6.5e-05 -0.059432" rpy="0 0 0"/>
  <parent link="left_upper_frame_1"/>
  <child link="left_upper_gearbox_1"/>
  <axis xyz="-0.996194 0.001062 0.087156"/>
</joint>

<joint name="rotate_11" type="continuous">
  <origin xyz="-0.066483 0.000111 -0.059432" rpy="0 0 0"/>
  <parent link="right_upper_frame_1"/>
  <child link="right_upper_gearbox_1"/>
  <axis xyz="-0.996193 0.001816 0.087156"/>
</joint>

<joint name="rotate_15" type="continuous">
  <origin xyz="0.09045 -0.050616 -0.008261" rpy="0 0 0"/>
  <parent link="right_upper_gearbox_1"/>
  <child link="right_middle_leg_1"/>
  <axis xyz="-0.001768 -0.999998 0.000629"/>
</joint>

<joint name="rotate_14" type="continuous">
  <origin xyz="0.090099 0.050354 -0.008205" rpy="0 0 0"/>
  <parent link="left_upper_gearbox_1"/>
  <child link="left_middle_leg_1"/>
  <axis xyz="0.001142 0.999999 0.000876"/>
</joint>

<joint name="rotate_16" type="continuous">
  <origin xyz="-0.022072 0.000243 -0.249024" rpy="0 0 0"/>
  <parent link="left_middle_leg_1"/>
  <child link="left_lower_leg_1"/>
  <axis xyz="0.001142 0.999999 0.000876"/>
</joint>

<joint name="rotate_17" type="continuous">
  <origin xyz="-0.022815 -0.000116 -0.248957" rpy="0 0 0"/>
  <parent link="right_middle_leg_1"/>
  <child link="right_lower_leg_1"/>
  <axis xyz="-0.001768 -0.999998 0.000629"/>
</joint>

<joint name="rotate_19" type="continuous">
  <origin xyz="-0.021782 -0.000118 -0.248973" rpy="0 0 0"/>
  <parent link="right_lower_leg_1"/>
  <child link="left_lower_gearbox_1"/>
  <axis xyz="-0.001768 -0.999998 0.000629"/>
</joint>

<joint name="rotate_18" type="continuous">
  <origin xyz="-0.021782 0.000243 -0.248972" rpy="0 0 0"/>
  <parent link="left_lower_leg_1"/>
  <child link="right_lower_gearbox_1"/>
  <axis xyz="0.001142 0.999999 0.000876"/>
</joint>

<joint name="rotate_21" type="continuous">
  <origin xyz="-0.091012 0.050716 0.007568" rpy="0 0 0"/>
  <parent link="left_lower_gearbox_1"/>
  <child link="left_foot_1"/>
  <axis xyz="-0.996193 0.001816 0.087156"/>
</joint>

<joint name="rotate_20" type="continuous">
  <origin xyz="-0.09116 -0.050452 0.007554" rpy="0 0 0"/>
  <parent link="right_lower_gearbox_1"/>
  <child link="right_foot_1"/>
  <axis xyz="-0.996194 0.001062 0.087156"/>
</joint>

</robot>
